Traceback (most recent call last):
  File "/scratch/lfs/mcintyre/python.git/fastq2fasta.py", line 35, in <module>
    main()
  File "/scratch/lfs/mcintyre/python.git/fastq2fasta.py", line 30, in main
    SeqIO.convert(args.fname, "fastq", args.out, "fasta")
  File "/apps/python/2.7.3/lib/python2.7/site-packages/biopython-1.63-py2.7-linux-x86_64.egg/Bio/SeqIO/__init__.py", line 984, in convert
    with as_handle(out_file, out_mode) as out_handle:
  File "/apps/python/2.7.3/lib/python2.7/contextlib.py", line 17, in __enter__
    return self.gen.next()
  File "/apps/python/2.7.3/lib/python2.7/site-packages/biopython-1.63-py2.7-linux-x86_64.egg/Bio/File.py", line 80, in as_handle
    with open(handleish, mode, **kwargs) as fp:
IOError: [Errno 2] No such file or directory: '/scratch/lfs/mcintyre/trago/qc_test/fasta_reads/Sample_Tm2/Tm2_AGTTCC_L002_R2_001.fastq.fa'
